<?xml version="1.0" ?>
<!-- =================================================================================== -->
<!-- |    This document was autogenerated by xacro from cubebot_3D.xacro               | -->
<!-- |    EDITING THIS FILE BY HAND IS NOT RECOMMENDED                                 | -->
<!-- =================================================================================== -->
<robot name="CubeBot">
  <material name="Black">
    <color rgba="0.1 0.1 0.1 1"/>
  </material>
  <material name="Grey">
    <color rgba="0.35 0.35 0.35 1"/>
  </material>
  <material name="Orange">
    <color rgba=".9569 .5372 .2588 1"/>
  </material>
  <material name="Blue">
    <color rgba=".0157 .1176 .6588 0.8"/>
  </material>
  <material name="Maize">
    <color rgba=".9451 .7686 0 1"/>
  </material>
  <material name="LightGrey">
    <color rgba="0.75 0.75 0.75 1"/>
  </material>
  <material name="Red">
    <color rgba="0.8 0.1 0.1 1"/>
  </material>
  <material name="Green">
    <color rgba="0.1 0.8 0.1 1"/>
  </material>
  <material name="Purple">
    <color rgba="0.8 0.1 0.8 1"/>
  </material>
  <link name="CubeBody">
    <visual>
      <origin rpy="0 0 0" xyz="0 0 0"/>
      <geometry>
        <box size="0.3 0.3 0.3"/>
      </geometry>
      <material name="Blue">
        <color rgba=".0157 .1176 .6588 0.8"/>
      </material>
    </visual>
    <collision>
      <origin rpy="0 0 0" xyz="0 0 0"/>
      <geometry>
        <box size="0.3 0.3 0.3"/>
      </geometry>
      <!-- <contact_coefficient mu="0"  resitution="0"  k_p="0"  k_d="0" /> -->
    </collision>
    <inertial>
      <origin rpy="0 0 0" xyz="0 0 0"/>
      <mass value="0.1"/>
      <inertia ixx="0.0015" ixy="0" ixz="0" iyy="0.0015" iyz="0.0" izz="0.0015"/>
    </inertial>
  </link>
  <link name="CornerBumper_1">
    <visual>
      <origin rpy="0 0 0" xyz="0 0 0"/>
      <geometry>
        <sphere radius="0.03"/>
      </geometry>
      <material name="Maize">
        <color rgba=".9451 .7686 0 1"/>
      </material>
    </visual>
    <collision>
      <origin rpy="0 0 0" xyz="0 0 0"/>
      <geometry>
        <sphere radius="0.03"/>
      </geometry>
      <!-- <contact_coefficient mu="0"  resitution="0"  k_p="0"  k_d="0" /> -->
    </collision>
    <inertial>
      <origin rpy="0 0 0" xyz="0 0 0"/>
      <mass value="0.01"/>
      <inertia ixx="3.6e-06" ixy="0" ixz="0" iyy="3.6e-06" iyz="0.0" izz="3.6e-06"/>
    </inertial>
  </link>
  <link name="CornerBumper_2">
    <visual>
      <origin rpy="0 0 0" xyz="0 0 0"/>
      <geometry>
        <sphere radius="0.03"/>
      </geometry>
      <material name="Red">
        <color rgba="0.8 0.1 0.1 1"/>
      </material>
    </visual>
    <collision>
      <origin rpy="0 0 0" xyz="0 0 0"/>
      <geometry>
        <sphere radius="0.03"/>
      </geometry>
      <!-- <contact_coefficient mu="0"  resitution="0"  k_p="0"  k_d="0" /> -->
    </collision>
    <inertial>
      <origin rpy="0 0 0" xyz="0 0 0"/>
      <mass value="0.01"/>
      <inertia ixx="3.6e-06" ixy="0" ixz="0" iyy="3.6e-06" iyz="0.0" izz="3.6e-06"/>
    </inertial>
  </link>
  <link name="CornerBumper_3">
    <visual>
      <origin rpy="0 0 0" xyz="0 0 0"/>
      <geometry>
        <sphere radius="0.03"/>
      </geometry>
      <material name="Red">
        <color rgba="0.8 0.1 0.1 1"/>
      </material>
    </visual>
    <collision>
      <origin rpy="0 0 0" xyz="0 0 0"/>
      <geometry>
        <sphere radius="0.03"/>
      </geometry>
      <!-- <contact_coefficient mu="0"  resitution="0"  k_p="0"  k_d="0" /> -->
    </collision>
    <inertial>
      <origin rpy="0 0 0" xyz="0 0 0"/>
      <mass value="0.01"/>
      <inertia ixx="3.6e-06" ixy="0" ixz="0" iyy="3.6e-06" iyz="0.0" izz="3.6e-06"/>
    </inertial>
  </link>
  <link name="CornerBumper_4">
    <visual>
      <origin rpy="0 0 0" xyz="0 0 0"/>
      <geometry>
        <sphere radius="0.03"/>
      </geometry>
      <material name="Red">
        <color rgba="0.8 0.1 0.1 1"/>
      </material>
    </visual>
    <collision>
      <origin rpy="0 0 0" xyz="0 0 0"/>
      <geometry>
        <sphere radius="0.03"/>
      </geometry>
      <!-- <contact_coefficient mu="0"  resitution="0"  k_p="0"  k_d="0" /> -->
    </collision>
    <inertial>
      <origin rpy="0 0 0" xyz="0 0 0"/>
      <mass value="0.01"/>
      <inertia ixx="3.6e-06" ixy="0" ixz="0" iyy="3.6e-06" iyz="0.0" izz="3.6e-06"/>
    </inertial>
  </link>
  <link name="CornerBumper_5">
    <visual>
      <origin rpy="0 0 0" xyz="0 0 0"/>
      <geometry>
        <sphere radius="0.03"/>
      </geometry>
      <material name="Red">
        <color rgba="0.8 0.1 0.1 1"/>
      </material>
    </visual>
    <collision>
      <origin rpy="0 0 0" xyz="0 0 0"/>
      <geometry>
        <sphere radius="0.03"/>
      </geometry>
      <!-- <contact_coefficient mu="0"  resitution="0"  k_p="0"  k_d="0" /> -->
    </collision>
    <inertial>
      <origin rpy="0 0 0" xyz="0 0 0"/>
      <mass value="0.01"/>
      <inertia ixx="3.6e-06" ixy="0" ixz="0" iyy="3.6e-06" iyz="0.0" izz="3.6e-06"/>
    </inertial>
  </link>
  <link name="CornerBumper_6">
    <visual>
      <origin rpy="0 0 0" xyz="0 0 0"/>
      <geometry>
        <sphere radius="0.03"/>
      </geometry>
      <material name="Red">
        <color rgba="0.8 0.1 0.1 1"/>
      </material>
    </visual>
    <collision>
      <origin rpy="0 0 0" xyz="0 0 0"/>
      <geometry>
        <sphere radius="0.03"/>
      </geometry>
      <!-- <contact_coefficient mu="0"  resitution="0"  k_p="0"  k_d="0" /> -->
    </collision>
    <inertial>
      <origin rpy="0 0 0" xyz="0 0 0"/>
      <mass value="0.01"/>
      <inertia ixx="3.6e-06" ixy="0" ixz="0" iyy="3.6e-06" iyz="0.0" izz="3.6e-06"/>
    </inertial>
  </link>
  <link name="CornerBumper_7">
    <visual>
      <origin rpy="0 0 0" xyz="0 0 0"/>
      <geometry>
        <sphere radius="0.03"/>
      </geometry>
      <material name="Red">
        <color rgba="0.8 0.1 0.1 1"/>
      </material>
    </visual>
    <collision>
      <origin rpy="0 0 0" xyz="0 0 0"/>
      <geometry>
        <sphere radius="0.03"/>
      </geometry>
      <!-- <contact_coefficient mu="0"  resitution="0"  k_p="0"  k_d="0" /> -->
    </collision>
    <inertial>
      <origin rpy="0 0 0" xyz="0 0 0"/>
      <mass value="0.01"/>
      <inertia ixx="3.6e-06" ixy="0" ixz="0" iyy="3.6e-06" iyz="0.0" izz="3.6e-06"/>
    </inertial>
  </link>
  <link name="CornerBumper_8">
    <visual>
      <origin rpy="0 0 0" xyz="0 0 0"/>
      <geometry>
        <sphere radius="0.03"/>
      </geometry>
      <material name="Red">
        <color rgba="0.8 0.1 0.1 1"/>
      </material>
    </visual>
    <collision>
      <origin rpy="0 0 0" xyz="0 0 0"/>
      <geometry>
        <sphere radius="0.03"/>
      </geometry>
      <!-- <contact_coefficient mu="0"  resitution="0"  k_p="0"  k_d="0" /> -->
    </collision>
    <inertial>
      <origin rpy="0 0 0" xyz="0 0 0"/>
      <mass value="0.01"/>
      <inertia ixx="3.6e-06" ixy="0" ixz="0" iyy="3.6e-06" iyz="0.0" izz="3.6e-06"/>
    </inertial>
  </link>
  <link name="InertialWheel_1">
    <visual>
      <origin rpy="0 0 0" xyz="0 0 0"/>
      <geometry>
        <cylinder length="0.01" radius="0.08"/>
      </geometry>
      <!-- <contact_coefficient mu="0"  resitution="0"  k_p="0"  k_d="0" /> -->
      <material name="Orange">
        <color rgba=".9569 .5372 .2588 1"/>
      </material>
    </visual>
    <inertial>
      <origin rpy="0 0 0" xyz="0 0 0"/>
      <mass value="0.25"/>
      <inertia ixx="0.0010270833333333334" ixy="0" ixz="0" iyy="0.0010270833333333334" iyz="0.0" izz="0.00205"/>
    </inertial>
  </link>
  <link name="InertialWheel_2">
    <visual>
      <origin rpy="0 0 0" xyz="0 0 0"/>
      <geometry>
        <cylinder length="0.01" radius="0.08"/>
      </geometry>
      <!-- <contact_coefficient mu="0"  resitution="0"  k_p="0"  k_d="0" /> -->
      <material name="Orange">
        <color rgba=".9569 .5372 .2588 1"/>
      </material>
    </visual>
    <inertial>
      <origin rpy="0 0 0" xyz="0 0 0"/>
      <mass value="0.25"/>
      <inertia ixx="0.0010270833333333334" ixy="0" ixz="0" iyy="0.0010270833333333334" iyz="0.0" izz="0.00205"/>
    </inertial>
  </link>
  <link name="InertialWheel_3">
    <visual>
      <origin rpy="0 0 0" xyz="0 0 0"/>
      <geometry>
        <cylinder length="0.01" radius="0.08"/>
      </geometry>
      <!-- <contact_coefficient mu="0"  resitution="0"  k_p="0"  k_d="0" /> -->
      <material name="Orange">
        <color rgba=".9569 .5372 .2588 1"/>
      </material>
    </visual>
    <inertial>
      <origin rpy="0 0 0" xyz="0 0 0"/>
      <mass value="0.25"/>
      <inertia ixx="0.0010270833333333334" ixy="0" ixz="0" iyy="0.0010270833333333334" iyz="0.0" izz="0.00205"/>
    </inertial>
  </link>
  <link name="InertialWheel_4">
    <visual>
      <origin rpy="0 0 0" xyz="0 0 0"/>
      <geometry>
        <cylinder length="0.01" radius="0.08"/>
      </geometry>
      <!-- <contact_coefficient mu="0"  resitution="0"  k_p="0"  k_d="0" /> -->
      <material name="Orange">
        <color rgba=".9569 .5372 .2588 1"/>
      </material>
    </visual>
    <inertial>
      <origin rpy="0 0 0" xyz="0 0 0"/>
      <mass value="0.25"/>
      <inertia ixx="0.0010270833333333334" ixy="0" ixz="0" iyy="0.0010270833333333334" iyz="0.0" izz="0.00205"/>
    </inertial>
  </link>
  <link name="InertialWheel_5">
    <visual>
      <origin rpy="0 0 0" xyz="0 0 0"/>
      <geometry>
        <cylinder length="0.01" radius="0.08"/>
      </geometry>
      <!-- <contact_coefficient mu="0"  resitution="0"  k_p="0"  k_d="0" /> -->
      <material name="Orange">
        <color rgba=".9569 .5372 .2588 1"/>
      </material>
    </visual>
    <inertial>
      <origin rpy="0 0 0" xyz="0 0 0"/>
      <mass value="0.25"/>
      <inertia ixx="0.0010270833333333334" ixy="0" ixz="0" iyy="0.0010270833333333334" iyz="0.0" izz="0.00205"/>
    </inertial>
  </link>
  <link name="InertialWheel_6">
    <visual>
      <origin rpy="0 0 0" xyz="0 0 0"/>
      <geometry>
        <cylinder length="0.01" radius="0.08"/>
      </geometry>
      <!-- <contact_coefficient mu="0"  resitution="0"  k_p="0"  k_d="0" /> -->
      <material name="Orange">
        <color rgba=".9569 .5372 .2588 1"/>
      </material>
    </visual>
    <inertial>
      <origin rpy="0 0 0" xyz="0 0 0"/>
      <mass value="0.25"/>
      <inertia ixx="0.0010270833333333334" ixy="0" ixz="0" iyy="0.0010270833333333334" iyz="0.0" izz="0.00205"/>
    </inertial>
  </link>
  <joint name="$fixed_CubeBody_CornerBumper_1" type="fixed">
    <origin rpy="0 0 0" xyz="0.15 0.15 0.15"/>
    <parent link="CubeBody"/>
    <child link="CornerBumper_1"/>
  </joint>
  <joint name="$fixed_CubeBody_CornerBumper_2" type="fixed">
    <origin rpy="0 0 0" xyz="-0.15 0.15 0.15"/>
    <parent link="CubeBody"/>
    <child link="CornerBumper_2"/>
  </joint>
  <joint name="$fixed_CubeBody_CornerBumper_3" type="fixed">
    <origin rpy="0 0 0" xyz="0.15 -0.15 0.15"/>
    <parent link="CubeBody"/>
    <child link="CornerBumper_3"/>
  </joint>
  <joint name="$fixed_CubeBody_CornerBumper_4" type="fixed">
    <origin rpy="0 0 0" xyz="-0.15 -0.15 0.15"/>
    <parent link="CubeBody"/>
    <child link="CornerBumper_4"/>
  </joint>
  <joint name="$fixed_CubeBody_CornerBumper_5" type="fixed">
    <origin rpy="0 0 0" xyz="0.15 0.15 -0.15"/>
    <parent link="CubeBody"/>
    <child link="CornerBumper_5"/>
  </joint>
  <joint name="$fixed_CubeBody_CornerBumper_6" type="fixed">
    <origin rpy="0 0 0" xyz="-0.15 0.15 -0.15"/>
    <parent link="CubeBody"/>
    <child link="CornerBumper_6"/>
  </joint>
  <joint name="$fixed_CubeBody_CornerBumper_7" type="fixed">
    <origin rpy="0 0 0" xyz="0.15 -0.15 -0.15"/>
    <parent link="CubeBody"/>
    <child link="CornerBumper_7"/>
  </joint>
  <joint name="$fixed_CubeBody_CornerBumper_8" type="fixed">
    <origin rpy="0 0 0" xyz="-0.15 -0.15 -0.15"/>
    <parent link="CubeBody"/>
    <child link="CornerBumper_8"/>
  </joint>
  <joint name="$continuous_CubeBody_InertialWheel_1" type="continuous">
    <origin rpy="0 1.57075 0" xyz="0.15 0 0"/>
    <parent link="CubeBody"/>
    <child link="InertialWheel_1"/>
    <axis xyz="0 0 1"/>
    <dynamics damping="0" friction="0"/>
  </joint>
  <joint name="$continuous_CubeBody_InertialWheel_2" type="continuous">
    <origin rpy="0 1.57075 0" xyz="-0.15 0 0"/>
    <parent link="CubeBody"/>
    <child link="InertialWheel_2"/>
    <axis xyz="0 0 1"/>
    <dynamics damping="0" friction="0"/>
  </joint>
  <joint name="$continuous_CubeBody_InertialWheel_3" type="continuous">
    <origin rpy="1.57075 0 0" xyz="0 0.15 0"/>
    <parent link="CubeBody"/>
    <child link="InertialWheel_3"/>
    <axis xyz="0 0 1"/>
    <dynamics damping="0" friction="0"/>
  </joint>
  <joint name="$continuous_CubeBody_InertialWheel_4" type="continuous">
    <origin rpy="1.57075 0 0" xyz="0 -0.15 0"/>
    <parent link="CubeBody"/>
    <child link="InertialWheel_4"/>
    <axis xyz="0 0 1"/>
    <dynamics damping="0" friction="0"/>
  </joint>
  <joint name="$continuous_CubeBody_InertialWheel_5" type="continuous">
    <origin rpy="0 0 1.57075" xyz="0 0 0.15"/>
    <parent link="CubeBody"/>
    <child link="InertialWheel_5"/>
    <axis xyz="0 0 1"/>
    <dynamics damping="0" friction="0"/>
  </joint>
  <joint name="$continuous_CubeBody_InertialWheel_6" type="continuous">
    <origin rpy="0 0 1.57075" xyz="0 0 -0.15"/>
    <parent link="CubeBody"/>
    <child link="InertialWheel_6"/>
    <axis xyz="0 0 1"/>
    <dynamics damping="0" friction="0"/>
  </joint>
</robot>
